<?xml version="1.0"?>
<sdf version="1.12">
  <model name="robot">
    <link name="base_link">
      <inertial>
        <pose>0.0 0.0 0.05 0.0 0.0 0.0</pose>
        <mass>1.0</mass>
        <inertia>
          <ixx>0.01</ixx>
          <ixy>0.0</ixy>
          <ixz>0.0</ixz>
          <iyy>0.01</iyy>
          <iyz>0.0</iyz>
          <izz>0.01</izz>
        </inertia>
      </inertial>
      <collision name="base_collision">
        <pose>0.0 0.0 0.05 0.0 0.0 0.0</pose>
        <geometry>
          <box>
            <size>0.2 0.2 0.1</size>
          </box>
        </geometry>
      </collision>
      <visual name="base_visual">
        <pose>0.0 0.0 0.05 0.0 0.0 0.0</pose>
        <geometry>
          <box>
            <size>0.2 0.2 0.1</size>
          </box>
        </geometry>
        <material>
          <script>
            <name>blue</name>
          </script>
          <diffuse>0.0 0.0 1.0 1.0</diffuse>
        </material>
      </visual>
    </link>

    <!-- robot-diff convention: link pose must be identity relative to parent joint -->
    <link name="link1">
      <pose relative_to="joint1"/>
      <inertial>
        <pose>0.0 0.0 0.25 0.0 0.0 0.0</pose>
        <mass>0.5</mass>
        <inertia>
          <ixx>0.005</ixx>
          <ixy>0.0</ixy>
          <ixz>0.0</ixz>
          <iyy>0.005</iyy>
          <iyz>0.0</iyz>
          <izz>0.001</izz>
        </inertia>
      </inertial>
      <collision name="link1_collision">
        <pose>0.0 0.0 0.25 0.0 0.0 0.0</pose>
        <geometry>
          <cylinder>
            <radius>0.05</radius>
            <length>0.5</length>
          </cylinder>
        </geometry>
      </collision>
      <visual name="link1_visual">
        <pose>0.0 0.0 0.25 0.0 0.0 0.0</pose>
        <geometry>
          <cylinder>
            <radius>0.05</radius>
            <length>0.5</length>
          </cylinder>
        </geometry>
        <material>
          <script>
            <name>red</name>
          </script>
          <diffuse>1.0 0.0 0.0 1.0</diffuse>
        </material>
      </visual>
    </link>

    <!-- robot-diff convention: link pose must be identity relative to parent joint -->
    <link name="link2">
      <pose relative_to="joint2"/>
      <inertial>
        <pose>0.0 0.0 0.0 0.0 0.0 0.0</pose>
        <mass>0.3</mass>
        <inertia>
          <ixx>0.001</ixx>
          <ixy>0.0</ixy>
          <ixz>0.0</ixz>
          <iyy>0.001</iyy>
          <iyz>0.0</iyz>
          <izz>0.001</izz>
        </inertia>
      </inertial>
      <collision name="link2_collision">
        <pose>0.0 0.0 0.0 0.0 0.0 0.0</pose>
        <geometry>
          <sphere>
            <radius>0.08</radius>
          </sphere>
        </geometry>
      </collision>
      <visual name="link2_visual">
        <pose>0.0 0.0 0.0 0.0 0.0 0.0</pose>
        <geometry>
          <mesh>
            <uri>meshes/link2.dae</uri>
            <scale>1.0 1.0 1.0</scale>
          </mesh>
        </geometry>
        <material>
          <script>
            <name>metal</name>
            <uri>textures/metal.png</uri>
          </script>
        </material>
      </visual>
    </link>

    <!-- robot-diff convention: joint pose must be relative to parent link -->
    <joint name="joint1" type="revolute">
      <pose relative_to="base_link">0.0 0.0 0.1 0.0 0.0 0.0</pose>
      <parent>base_link</parent>
      <child>link1</child>
      <axis>
        <xyz>0.0 0.0 1.0</xyz>
        <limit>
          <lower>-1.57</lower>
          <upper>1.57</upper>
          <effort>10.0</effort>
          <velocity>1.0</velocity>
        </limit>
      </axis>
    </joint>

    <!-- robot-diff convention: joint pose must be relative to parent link -->
    <joint name="joint2" type="prismatic">
      <pose relative_to="link1">0.0 0.0 0.5 0.0 0.0 0.0</pose>
      <parent>link1</parent>
      <child>link2</child>
      <axis>
        <xyz>0.0 0.0 1.0</xyz>
        <limit>
          <lower>0.0</lower>
          <upper>0.3</upper>
          <effort>5.0</effort>
          <velocity>0.5</velocity>
        </limit>
      </axis>
    </joint>
  </model>
</sdf>
